<?xml version="1.0" encoding="ASCII"?>
<robot name="R2D2" version="1.0">
  <material name="blue">
    <color rgba="0.0 0.0 0.8 1.0"/>
  </material>
  <material name="white">
    <color rgba="1.0 1.0 1.0 1.0"/>          
  </material>  
 <material name="black">
    <color rgba="0.0 0.0 0.0 1.0"/>
  </material>        
  <material name="metal">  
    <texture filename="textures/metal.jpg"/>    
  </material>    
  <link name="extension-base">
    <visual>
      <geometry>
        <box size="0.08 0.08 0.08"/>
      </geometry>      
      <material name="white"/>
    </visual>
  </link>
  <link name="base-link">
    <visual>
      <geometry>
        <cylinder radius="0.2" length="0.6"/>
      </geometry>
      <material name="blue"/>
    </visual>
  </link>
  <link name="right-leg">
    <visual>
      <origin xyz="0.0 0.0 -0.3" rpy="0.0 1.57075 0.0"/>
      <geometry>
        <box size="0.6 0.1 0.2"/>
      </geometry>
      <material name="white"/>
    </visual>
  </link>
  <link name="right-base">
    <visual>
      <geometry>
        <box size="0.4 0.1 0.1"/>
      </geometry>
      <material name="white"/>
    </visual>
  </link>
  <link name="left-leg">
    <visual>
      <origin xyz="0.0 0.0 -0.3" rpy="0.0 1.57075 0.0"/>
      <geometry>
        <box size="0.6 0.1 0.2"/>
      </geometry>
      <material name="white"/>
    </visual>
  </link>
  <link name="left-base">
    <visual>
      <geometry>
        <box size="0.4 0.1 0.1"/>
      </geometry>
      <material name="white"/>
    </visual>
  </link>
  <link name="right-front-wheel">
    <visual>
      <origin xyz="0.0 0.0 0.0" rpy="1.57075 0.0 0.0"/>
      <geometry>
        <cylinder radius="0.035" length="0.1"/>
      </geometry>
      <material name="black"/>
    </visual>
  </link>
  <link name="right-back-wheel">
    <visual>
      <origin xyz="0.0 0.0 0.0" rpy="1.57075 0.0 0.0"/>
      <geometry>
        <cylinder radius="0.035" length="0.1"/>
      </geometry>
      <material name="black"/>
    </visual>
  </link>
  <link name="left-front-wheel">
    <visual>
      <origin xyz="0.0 0.0 0.0" rpy="1.57075 0.0 0.0"/>
      <geometry>
        <cylinder radius="0.035" length="0.1"/>
      </geometry>
      <material name="black"/>
    </visual>
  </link>
  <link name="left-back-wheel">
    <visual>
      <origin xyz="0.0 0.0 0.0" rpy="1.57075 0.0 0.0"/>
      <geometry>
        <cylinder radius="0.035" length="0.1"/>
      </geometry>
      <material name="metal"/>
    </visual>
  </link>
  <link name="gripper-pole">
    <visual>
      <origin xyz="0.1 0.0 0.0" rpy="0.0 1.57075 0.0"/>
      <geometry>
        <cylinder radius="0.01" length="0.2"/>
      </geometry>
      <material name="metal"/>
    </visual>
  </link>
  <link name="left-gripper">
    <visual>
      <geometry>
        <mesh filename="meshes/l_finger.stl" scale="0.1 0.1 0.1"/>
      </geometry>
      <material name="metal"/>
    </visual>
  </link>
  <link name="right-gripper">
    <visual>
      <origin xyz="0.0 0.0 0.0" rpy="-3.1415 0.0 0.0"/>
      <geometry>
        <mesh filename="meshes/l_finger.stl" scale="0.1 0.1 0.1"/>
      </geometry>
      <material name="metal"/>
    </visual>
  </link>
  <link name="left-tip">
    <visual>
      <origin xyz="0.09137 0.00495 0.0" rpy="0.0 0.0 0.0"/>
      <geometry>
        <mesh filename="meshes/l_finger_tip.stl" scale="0.1 0.1 0.1"/>
      </geometry>
      <material name="metal"/>
    </visual>
  </link>
  <link name="right-tip">
    <visual>
      <origin xyz="0.09137 0.00495 0.0" rpy="-3.1415 0.0 0.0"/>
      <geometry>
        <mesh filename="meshes/l_finger_tip.stl" scale="0.1 0.1 0.1"/>
      </geometry>
      <material name="metal"/>
    </visual>
  </link>
  <link name="head">
    <visual>
      <origin xyz="0.0 0.0 0.3" rpy="0.0 1.57075 0.0"/>
      <geometry>
        <sphere radius="0.2"/>
      </geometry>
      <material name="white"/>
    </visual>
  </link>
  <joint name="head-swivel" >
    <origin xyz="0.0 0.0 0.03"/>    
    <parent link="base-link"/>
    <child link="head"/>
  </joint>
  <joint name="tobox" type="fixed">
    <origin xyz="0.1814 0.0 0.1414"/>
    <parent link="head"/>
    <child link="extension-base"/>
  </joint>
  <joint name="base-to-right-leg" type="fixed">
    <origin xyz="0.0 -0.22 0.25"/>
    <parent link="base-link"/>
    <child link="right-leg"/>
  </joint>
  <joint name="base-to-left-leg" type="fixed">
    <origin xyz="0.0 0.22 0.25"/>
    <parent link="base-link"/>
    <child link="left-leg"/>
  </joint>
  <joint name="right-base" type="fixed">
    <origin xyz="0.0 0.0 -0.6"/>
    <parent link="right-leg"/>
    <child link="right-base"/>
  </joint>
  <joint name="right-front-wheel" type="fixed">
    <origin xyz="0.133333333333 0.0 -0.085"/>
    <parent link="right-base"/>
    <child link="right-front-wheel"/>
  </joint>
  <joint name="left-front-wheel" type="fixed">
    <origin xyz="0.133333333333 0.0 -0.085"/>
    <parent link="left-base"/>
    <child link="left-front-wheel"/>
  </joint>
  <joint name="left-back-wheel" type="fixed">
    <origin xyz="-0.133333333333 0.0 -0.085"/>
    <parent link="left-base"/>
    <child link="left-back-wheel"/>
  </joint>
  <joint name="right-back-wheel" type="fixed">
    <origin xyz="-0.133333333333 0.0 -0.085"/>
    <parent link="right-base"/>
    <child link="right-back-wheel"/>
  </joint>
  <joint name="left-base" type="fixed">
    <origin xyz="0.0 0.0 -0.6"/>
    <parent link="left-leg"/>
    <child link="left-base"/>
  </joint>
  <joint name="extension" type="revolute">
    <origin xyz="0.19 0.0 0.2"/>
    <parent link="base-link"/>
    <child link="gripper-pole"/>
    <axis xyz="1.0 0.0 0.0"/>
    <limit lower="-1.5707" upper="1.5707"/>
  </joint>
  <joint name="left-gripper" type="fixed">
    <origin xyz="0.2 0.01 0.0"/>
    <parent link="gripper-pole"/>
    <child link="left-gripper"/>
  </joint>
  <joint name="left-tip" type="fixed">
    <parent link="left-gripper"/>
    <child link="left-tip"/>
  </joint>
  <joint name="right-gripper" type="fixed">
    <origin xyz="0.2 -0.01 0.0"/>
    <parent link="gripper-pole"/>
    <child link="right-gripper"/>
  </joint>
  <joint name="right-tip" type="fixed">
    <parent link="right-gripper"/>
    <child link="right-tip"/>
  </joint>  
</robot>
